2024-08-29 15:13:17,909 INFO    StreamThr :10452 [internal.py:wandb_internal():85] W&B internal server running at pid: 10452, started at: 2024-08-29 15:13:17.909454
2024-08-29 15:13:17,910 DEBUG   HandlerThread:10452 [handler.py:handle_request():158] handle_request: status
2024-08-29 15:13:17,914 INFO    WriterThread:10452 [datastore.py:open_for_write():87] open: C:\Users\a_ld7\PycharmProjects\businessCardAI\wandb\run-20240829_151317-03yhkivp\run-03yhkivp.wandb
2024-08-29 15:13:17,914 DEBUG   SenderThread:10452 [sender.py:send():391] send: header
2024-08-29 15:13:17,916 DEBUG   SenderThread:10452 [sender.py:send():391] send: run
2024-08-29 15:13:18,579 ERROR   SenderThread:10452 [internal_api.py:execute():349] 403 response executing GraphQL.
2024-08-29 15:13:18,579 ERROR   SenderThread:10452 [internal_api.py:execute():350] {"errors":[{"message":"permission denied","path":["upsertBucket"],"extensions":{"code":"PERMISSION_ERROR"}}],"data":{"upsertBucket":null}}
2024-08-29 15:13:18,583 ERROR   SenderThread:10452 [sender.py:send_run():1021] It appears that you do not have permission to access the requested resource. Please reach out to the project owner to grant you access. If you have the correct permissions, verify that there are no issues with your networking setup.(Error 403: Forbidden)
Traceback (most recent call last):
  File "C:\Users\a_ld7\PycharmProjects\businessCardAI\venv\lib\site-packages\wandb\sdk\lib\retry.py", line 131, in __call__
    result = self._call_fn(*args, **kwargs)
  File "C:\Users\a_ld7\PycharmProjects\businessCardAI\venv\lib\site-packages\wandb\sdk\internal\internal_api.py", line 345, in execute
    return self.client.execute(*args, **kwargs)  # type: ignore
  File "C:\Users\a_ld7\PycharmProjects\businessCardAI\venv\lib\site-packages\wandb\vendor\gql-0.2.0\wandb_gql\client.py", line 52, in execute
    result = self._get_result(document, *args, **kwargs)
  File "C:\Users\a_ld7\PycharmProjects\businessCardAI\venv\lib\site-packages\wandb\vendor\gql-0.2.0\wandb_gql\client.py", line 60, in _get_result
    return self.transport.execute(document, *args, **kwargs)
  File "C:\Users\a_ld7\PycharmProjects\businessCardAI\venv\lib\site-packages\wandb\sdk\lib\gql_request.py", line 59, in execute
    request.raise_for_status()
  File "C:\Users\a_ld7\PycharmProjects\businessCardAI\venv\lib\site-packages\requests\models.py", line 1024, in raise_for_status
    raise HTTPError(http_error_msg, response=self)
requests.exceptions.HTTPError: 403 Client Error: Forbidden for url: https://api.wandb.ai/graphql

During handling of the above exception, another exception occurred:

Traceback (most recent call last):
  File "C:\Users\a_ld7\PycharmProjects\businessCardAI\venv\lib\site-packages\wandb\sdk\internal\sender.py", line 1019, in send_run
    server_run = self._init_run(run, config_value_dict)
  File "C:\Users\a_ld7\PycharmProjects\businessCardAI\venv\lib\site-packages\wandb\sdk\internal\sender.py", line 1091, in _init_run
    server_run, inserted, server_messages = self._api.upsert_run(
  File "C:\Users\a_ld7\PycharmProjects\businessCardAI\venv\lib\site-packages\wandb\apis\normalize.py", line 73, in wrapper
    raise err
  File "C:\Users\a_ld7\PycharmProjects\businessCardAI\venv\lib\site-packages\wandb\apis\normalize.py", line 41, in wrapper
    return func(*args, **kwargs)
  File "C:\Users\a_ld7\PycharmProjects\businessCardAI\venv\lib\site-packages\wandb\sdk\internal\internal_api.py", line 2224, in upsert_run
    response = self.gql(
  File "C:\Users\a_ld7\PycharmProjects\businessCardAI\venv\lib\site-packages\wandb\sdk\internal\internal_api.py", line 317, in gql
    ret = self._retry_gql(
  File "C:\Users\a_ld7\PycharmProjects\businessCardAI\venv\lib\site-packages\wandb\sdk\lib\retry.py", line 147, in __call__
    retry_timedelta_triggered = check_retry_fn(e)
  File "C:\Users\a_ld7\PycharmProjects\businessCardAI\venv\lib\site-packages\wandb\util.py", line 968, in check_retry_fn
    return fallback_retry_fn(e)
  File "C:\Users\a_ld7\PycharmProjects\businessCardAI\venv\lib\site-packages\wandb\util.py", line 910, in no_retry_auth
    raise CommError(
wandb.errors.CommError: It appears that you do not have permission to access the requested resource. Please reach out to the project owner to grant you access. If you have the correct permissions, verify that there are no issues with your networking setup.(Error 403: Forbidden)
2024-08-29 15:13:23,622 DEBUG   HandlerThread:10452 [handler.py:handle_request():158] handle_request: status_report
2024-08-29 15:13:23,962 INFO    MainThread:10452 [internal.py:handle_exit():75] Internal process exited
